Workbook

Sheet Guide
B1: Sprint Health & Flow Dashboard: Guide
B2: Built with Jira data and Excel. All numbers in the demo are synthetic (no real company data).
B4: TABS
B5: Dashboard | C5: Headline KPIs, auto-written insights and four charts.
B6: Sprint_Metrics | C6: Per-sprint committed vs completed, throughput, velocity, cycle time. Calculated from Jira_Data.
B7: Forecast | C7: Monte Carlo forecast: how many sprints until the remaining backlog is done, at your chosen confidence.
B8: Simulation | C8: 500 trials behind the forecast (random, recalculates with F9). No need to edit.
B9: Jira_Data | C9: Sample Jira export. Paste your own data here (columns A to I).
B11: HOW TO USE WITH YOUR OWN DATA
B12: 1. Export from Jira | C12: Filter issues > Export > CSV. Keep: Issue key, Summary, Issue Type, Status, Story point estimate, Sprint, Created, Resolved.
B13: 2. Get 'Started' dates | C13: Jira CSVs do not include when work began. Use a Jira automation rule or the issue history to capture the date an issue first moved to In Progress.
B14: 3. Paste into Jira_Data | C14: Match the column order in row 1 and use real dates. Columns J and K are formulas, already filled to row 500.
B15: 4. Set the sprint inputs | C15: On Sprint_Metrics, set the first sprint start date and sprint length. Rename sprints in column A to match your Jira sprint names.
B16: 5. Press F9 | C16: Refreshes the Monte Carlo forecast. Change the confidence level or override remaining items on the Forecast tab.
B18: LEGEND
B19: Blue text on yellow | C19: Input cells you can change.
B20: Black text | C20: Formulas. Do not overwrite.
B22: ASSUMPTIONS
B23: Cycle time | C23: Calendar days from Started to Resolved. Lead time is Created to Resolved.
B24: Throughput / velocity | C24: Counted in the sprint whose dates contain the Resolved date, so spillover work is credited where it finished.
B25: Forecast method | C25: Each trial draws 8 sprints of throughput at random from history. It assumes future pace resembles the past and that backlog items are similarly sized.
B26: Sprint dates | C26: Sprints are assumed to run back to back with the same length.

Sheet Dashboard
B1: Sprint Health & Flow Dashboard
B2: Demo with synthetic Jira data (10 sprints). Replace the Jira_Data tab with your own export to refresh everything.
B4: Avg velocity (pts / sprint) | D4: Avg throughput (items / sprint) | F4: Median cycle time (days) | H4: 85th pct cycle time (days)
B5: =Sprint_Metrics!G17 -> 23.1 | D5: =Sprint_Metrics!F17 -> 9 | F5: =MEDIAN(Jira_Data!$J$2:$J$500) -> 4 | H5: =PERCENTILE(Jira_Data!$J$2:$J$500,0.85) -> 9
B7: Points done ÷ committed | D7: Velocity variability (CV) | F7: Bug share of all issues | H7: Open work items
B8: =SUM(Sprint_Metrics!G7:G16)/SUM(Sprint_Metrics!E7:E16) -> 0.93145161 | D8: =STDEV(Sprint_Metrics!$G$7:$G$16)/AVERAGE(Sprint_Metrics!$G$7:$G$16) -> 0.21640211 | F8: =COUNTIF(Jira_Data!$C$2:$C$500,"Bug")/COUNTA(Jira_Data!$A$2:$A$500) -> 0.21666667 | H8: =COUNTA(Jira_Data!$A$2:$A$500)-COUNTIF(Jira_Data!$D$2:$D$500,"Done") -> 24
B10: What the data says
B11: ="Flow: 85% of items finish within "&TEXT(H5,"0")&" days of starting. Use this as a service-level expectation when stakeholders ask how long work takes." -> Flow: 85% of items finish within 9 days of starting. Use this as a service-level expectation when stakeholders ask how long work takes.
B12: ="Predictability: the team delivers "&TEXT(B8,"0%")&" of the points it commits to per sprint, and velocity varies by about "&TEXT(D8,"0%")&" sprint to sprint (lower is steadier)." -> Predictability: the team delivers 93% of the points it commits to per sprint, and velocity varies by about 22% sprint to sprint (lower is steadier).
B13: ="Quality: bugs make up "&TEXT(F8,"0%")&" of all issues. Track whether this trends down as quality practices improve." -> Quality: bugs make up 22% of all issues. Track whether this trends down as quality practices improve.
B14: ="Forecast: with "&Forecast!B5&" items remaining, there is "&TEXT(Forecast!B6,"0%")&" confidence of finishing within "&Forecast!B22&" sprint(s) (by "&IF(ISNUMBER(Forecast!B23),TEXT(Forecast!B23,"dd mmm yyyy"),Forecast!B23)&")." -> Forecast: with 24 items remaining, there is 85% confidence of finishing within 3 sprint(s) (by 30 Aug 2026).

Sheet Sprint_Metrics
A1: Sprint Metrics
A2: One row per closed sprint. Everything is calculated from Jira_Data. Edit only the yellow cells.
A3: Sprint length (days) | B3: 14
A4: First sprint start date | B4: 46083
A6: Sprint | B6: Start | C6: End | D6: Committed items | E6: Committed points | F6: Throughput (items done) | G6: Velocity (points done) | H6: Points done ÷ committed | I6: Avg cycle time (days) | J6: Bugs resolved
A7: Sprint 1 | B7: =$B$4 -> 46083 | C7: =B7+$B$3-1 -> 46096 | D7: =COUNTIF(Jira_Data!$F$2:$F$500,A7) -> 10 | E7: =SUMIFS(Jira_Data!$E$2:$E$500,Jira_Data!$F$2:$F$500,A7) -> 20 | F7: =COUNTIFS(Jira_Data!$I$2:$I$500,">="&B7,Jira_Data!$I$2:$I$500,"<="&C7) -> 8 | G7: =SUMIFS(Jira_Data!$E$2:$E$500,Jira_Data!$I$2:$I$500,">="&B7,Jira_Data!$I$2:$I$500,"<="&C7) -> 17 | H7: =IF(E7=0,0,G7/E7) -> 0.85 | I7: =IFERROR(AVERAGEIFS(Jira_Data!$J$2:$J$500,Jira_Data!$I$2:$I$500,">="&B7,Jira_Data!$I$2:$I$500,"<="&C7),0) -> 4 | J7: =COUNTIFS(Jira_Data!$C$2:$C$500,"Bug",Jira_Data!$I$2:$I$500,">="&B7,Jira_Data!$I$2:$I$500,"<="&C7) -> 4
A8: Sprint 2 | B8: =C7+1 -> 46097 | C8: =B8+$B$3-1 -> 46110 | D8: =COUNTIF(Jira_Data!$F$2:$F$500,A8) -> 11 | E8: =SUMIFS(Jira_Data!$E$2:$E$500,Jira_Data!$F$2:$F$500,A8) -> 21 | F8: =COUNTIFS(Jira_Data!$I$2:$I$500,">="&B8,Jira_Data!$I$2:$I$500,"<="&C8) -> 11 | G8: =SUMIFS(Jira_Data!$E$2:$E$500,Jira_Data!$I$2:$I$500,">="&B8,Jira_Data!$I$2:$I$500,"<="&C8) -> 18 | H8: =IF(E8=0,0,G8/E8) -> 0.85714286 | I8: =IFERROR(AVERAGEIFS(Jira_Data!$J$2:$J$500,Jira_Data!$I$2:$I$500,">="&B8,Jira_Data!$I$2:$I$500,"<="&C8),0) -> 3.9090909 | J8: =COUNTIFS(Jira_Data!$C$2:$C$500,"Bug",Jira_Data!$I$2:$I$500,">="&B8,Jira_Data!$I$2:$I$500,"<="&C8) -> 3
A9: Sprint 3 | B9: =C8+1 -> 46111 | C9: =B9+$B$3-1 -> 46124 | D9: =COUNTIF(Jira_Data!$F$2:$F$500,A9) -> 9 | E9: =SUMIFS(Jira_Data!$E$2:$E$500,Jira_Data!$F$2:$F$500,A9) -> 21 | F9: =COUNTIFS(Jira_Data!$I$2:$I$500,">="&B9,Jira_Data!$I$2:$I$500,"<="&C9) -> 8 | G9: =SUMIFS(Jira_Data!$E$2:$E$500,Jira_Data!$I$2:$I$500,">="&B9,Jira_Data!$I$2:$I$500,"<="&C9) -> 21 | H9: =IF(E9=0,0,G9/E9) -> 1 | I9: =IFERROR(AVERAGEIFS(Jira_Data!$J$2:$J$500,Jira_Data!$I$2:$I$500,">="&B9,Jira_Data!$I$2:$I$500,"<="&C9),0) -> 4.625 | J9: =COUNTIFS(Jira_Data!$C$2:$C$500,"Bug",Jira_Data!$I$2:$I$500,">="&B9,Jira_Data!$I$2:$I$500,"<="&C9) -> 2
A10: Sprint 4 | B10: =C9+1 -> 46125 | C10: =B10+$B$3-1 -> 46138 | D10: =COUNTIF(Jira_Data!$F$2:$F$500,A10) -> 9 | E10: =SUMIFS(Jira_Data!$E$2:$E$500,Jira_Data!$F$2:$F$500,A10) -> 17 | F10: =COUNTIFS(Jira_Data!$I$2:$I$500,">="&B10,Jira_Data!$I$2:$I$500,"<="&C10) -> 11 | G10: =SUMIFS(Jira_Data!$E$2:$E$500,Jira_Data!$I$2:$I$500,">="&B10,Jira_Data!$I$2:$I$500,"<="&C10) -> 22 | H10: =IF(E10=0,0,G10/E10) -> 1.2941176 | I10: =IFERROR(AVERAGEIFS(Jira_Data!$J$2:$J$500,Jira_Data!$I$2:$I$500,">="&B10,Jira_Data!$I$2:$I$500,"<="&C10),0) -> 6.4545455 | J10: =COUNTIFS(Jira_Data!$C$2:$C$500,"Bug",Jira_Data!$I$2:$I$500,">="&B10,Jira_Data!$I$2:$I$500,"<="&C10) -> 2
A11: Sprint 5 | B11: =C10+1 -> 46139 | C11: =B11+$B$3-1 -> 46152 | D11: =COUNTIF(Jira_Data!$F$2:$F$500,A11) -> 8 | E11: =SUMIFS(Jira_Data!$E$2:$E$500,Jira_Data!$F$2:$F$500,A11) -> 27 | F11: =COUNTIFS(Jira_Data!$I$2:$I$500,">="&B11,Jira_Data!$I$2:$I$500,"<="&C11) -> 8 | G11: =SUMIFS(Jira_Data!$E$2:$E$500,Jira_Data!$I$2:$I$500,">="&B11,Jira_Data!$I$2:$I$500,"<="&C11) -> 25 | H11: =IF(E11=0,0,G11/E11) -> 0.92592593 | I11: =IFERROR(AVERAGEIFS(Jira_Data!$J$2:$J$500,Jira_Data!$I$2:$I$500,">="&B11,Jira_Data!$I$2:$I$500,"<="&C11),0) -> 5 | J11: =COUNTIFS(Jira_Data!$C$2:$C$500,"Bug",Jira_Data!$I$2:$I$500,">="&B11,Jira_Data!$I$2:$I$500,"<="&C11) -> 3
A12: Sprint 6 | B12: =C11+1 -> 46153 | C12: =B12+$B$3-1 -> 46166 | D12: =COUNTIF(Jira_Data!$F$2:$F$500,A12) -> 9 | E12: =SUMIFS(Jira_Data!$E$2:$E$500,Jira_Data!$F$2:$F$500,A12) -> 30 | F12: =COUNTIFS(Jira_Data!$I$2:$I$500,">="&B12,Jira_Data!$I$2:$I$500,"<="&C12) -> 7 | G12: =SUMIFS(Jira_Data!$E$2:$E$500,Jira_Data!$I$2:$I$500,">="&B12,Jira_Data!$I$2:$I$500,"<="&C12) -> 20 | H12: =IF(E12=0,0,G12/E12) -> 0.66666667 | I12: =IFERROR(AVERAGEIFS(Jira_Data!$J$2:$J$500,Jira_Data!$I$2:$I$500,">="&B12,Jira_Data!$I$2:$I$500,"<="&C12),0) -> 6.2857143 | J12: =COUNTIFS(Jira_Data!$C$2:$C$500,"Bug",Jira_Data!$I$2:$I$500,">="&B12,Jira_Data!$I$2:$I$500,"<="&C12) -> 0
A13: Sprint 7 | B13: =C12+1 -> 46167 | C13: =B13+$B$3-1 -> 46180 | D13: =COUNTIF(Jira_Data!$F$2:$F$500,A13) -> 9 | E13: =SUMIFS(Jira_Data!$E$2:$E$500,Jira_Data!$F$2:$F$500,A13) -> 19 | F13: =COUNTIFS(Jira_Data!$I$2:$I$500,">="&B13,Jira_Data!$I$2:$I$500,"<="&C13) -> 9 | G13: =SUMIFS(Jira_Data!$E$2:$E$500,Jira_Data!$I$2:$I$500,">="&B13,Jira_Data!$I$2:$I$500,"<="&C13) -> 22 | H13: =IF(E13=0,0,G13/E13) -> 1.1578947 | I13: =IFERROR(AVERAGEIFS(Jira_Data!$J$2:$J$500,Jira_Data!$I$2:$I$500,">="&B13,Jira_Data!$I$2:$I$500,"<="&C13),0) -> 5.5555556 | J13: =COUNTIFS(Jira_Data!$C$2:$C$500,"Bug",Jira_Data!$I$2:$I$500,">="&B13,Jira_Data!$I$2:$I$500,"<="&C13) -> 2
A14: Sprint 8 | B14: =C13+1 -> 46181 | C14: =B14+$B$3-1 -> 46194 | D14: =COUNTIF(Jira_Data!$F$2:$F$500,A14) -> 11 | E14: =SUMIFS(Jira_Data!$E$2:$E$500,Jira_Data!$F$2:$F$500,A14) -> 34 | F14: =COUNTIFS(Jira_Data!$I$2:$I$500,">="&B14,Jira_Data!$I$2:$I$500,"<="&C14) -> 12 | G14: =SUMIFS(Jira_Data!$E$2:$E$500,Jira_Data!$I$2:$I$500,">="&B14,Jira_Data!$I$2:$I$500,"<="&C14) -> 31 | H14: =IF(E14=0,0,G14/E14) -> 0.91176471 | I14: =IFERROR(AVERAGEIFS(Jira_Data!$J$2:$J$500,Jira_Data!$I$2:$I$500,">="&B14,Jira_Data!$I$2:$I$500,"<="&C14),0) -> 5.4166667 | J14: =COUNTIFS(Jira_Data!$C$2:$C$500,"Bug",Jira_Data!$I$2:$I$500,">="&B14,Jira_Data!$I$2:$I$500,"<="&C14) -> 2
A15: Sprint 9 | B15: =C14+1 -> 46195 | C15: =B15+$B$3-1 -> 46208 | D15: =COUNTIF(Jira_Data!$F$2:$F$500,A15) -> 9 | E15: =SUMIFS(Jira_Data!$E$2:$E$500,Jira_Data!$F$2:$F$500,A15) -> 34 | F15: =COUNTIFS(Jira_Data!$I$2:$I$500,">="&B15,Jira_Data!$I$2:$I$500,"<="&C15) -> 7 | G15: =SUMIFS(Jira_Data!$E$2:$E$500,Jira_Data!$I$2:$I$500,">="&B15,Jira_Data!$I$2:$I$500,"<="&C15) -> 23 | H15: =IF(E15=0,0,G15/E15) -> 0.67647059 | I15: =IFERROR(AVERAGEIFS(Jira_Data!$J$2:$J$500,Jira_Data!$I$2:$I$500,">="&B15,Jira_Data!$I$2:$I$500,"<="&C15),0) -> 4.4285714 | J15: =COUNTIFS(Jira_Data!$C$2:$C$500,"Bug",Jira_Data!$I$2:$I$500,">="&B15,Jira_Data!$I$2:$I$500,"<="&C15) -> 1
A16: Sprint 10 | B16: =C15+1 -> 46209 | C16: =B16+$B$3-1 -> 46222 | D16: =COUNTIF(Jira_Data!$F$2:$F$500,A16) -> 11 | E16: =SUMIFS(Jira_Data!$E$2:$E$500,Jira_Data!$F$2:$F$500,A16) -> 25 | F16: =COUNTIFS(Jira_Data!$I$2:$I$500,">="&B16,Jira_Data!$I$2:$I$500,"<="&C16) -> 9 | G16: =SUMIFS(Jira_Data!$E$2:$E$500,Jira_Data!$I$2:$I$500,">="&B16,Jira_Data!$I$2:$I$500,"<="&C16) -> 32 | H16: =IF(E16=0,0,G16/E16) -> 1.28 | I16: =IFERROR(AVERAGEIFS(Jira_Data!$J$2:$J$500,Jira_Data!$I$2:$I$500,">="&B16,Jira_Data!$I$2:$I$500,"<="&C16),0) -> 7.8888889 | J16: =COUNTIFS(Jira_Data!$C$2:$C$500,"Bug",Jira_Data!$I$2:$I$500,">="&B16,Jira_Data!$I$2:$I$500,"<="&C16) -> 1
A17: Average | D17: =AVERAGE(D7:D16) -> 9.6 | E17: =AVERAGE(E7:E16) -> 24.8 | F17: =AVERAGE(F7:F16) -> 9 | G17: =AVERAGE(G7:G16) -> 23.1 | H17: =AVERAGE(H7:H16) -> 0.96199831 | I17: =AVERAGE(I7:I16) -> 5.3564033 | J17: =AVERAGE(J7:J16) -> 2
A19: Notes: 'Throughput' and 'Velocity' count items/points whose Resolved date falls inside the sprint dates, so work that spills over is credited to the sprint where it actually finished. 'Committed' counts items tagged with that sprint in Jira_Data column F.

Sheet Forecast
A1: Monte Carlo Delivery Forecast
A2: Each of 500 trials randomly re-plays past sprint throughput to estimate how many items get done. Press F9 to re-run the simulation.
A3: Items remaining (auto from Jira_Data) | B3: =COUNTA(Jira_Data!$A$2:$A$500)-COUNTIF(Jira_Data!$D$2:$D$500,"Done") -> 24
A4: Override remaining items (optional)
A5: Items used in forecast | B5: =IF(B4<>"",B4,B3) -> 24
A6: Confidence level | B6: 0.85
A7: Next sprint start | B7: =Sprint_Metrics!C16+1 -> 46223
A8: Sprint length (days) | B8: =Sprint_Metrics!B3 -> 14
A9: Number of trials | B9: =COUNT(Simulation!A2:A501) -> 500
A12: Sprints from now | B12: Probability backlog is done | C12: Meets confidence level? | D12: End of that sprint
A13: 1 | B13: =COUNTIF(Simulation!$J$2:$J$501,">="&$B$5)/$B$9 -> 0 | C13: =IF(B13>=$B$6,"Yes","No") -> No | D13: =$B$7+A13*$B$8-1 -> 46236
A14: 2 | B14: =COUNTIF(Simulation!$K$2:$K$501,">="&$B$5)/$B$9 -> 0.014 | C14: =IF(B14>=$B$6,"Yes","No") -> No | D14: =$B$7+A14*$B$8-1 -> 46250
A15: 3 | B15: =COUNTIF(Simulation!$L$2:$L$501,">="&$B$5)/$B$9 -> 0.862 | C15: =IF(B15>=$B$6,"Yes","No") -> Yes | D15: =$B$7+A15*$B$8-1 -> 46264
A16: 4 | B16: =COUNTIF(Simulation!$M$2:$M$501,">="&$B$5)/$B$9 -> 1 | C16: =IF(B16>=$B$6,"Yes","No") -> Yes | D16: =$B$7+A16*$B$8-1 -> 46278
A17: 5 | B17: =COUNTIF(Simulation!$N$2:$N$501,">="&$B$5)/$B$9 -> 1 | C17: =IF(B17>=$B$6,"Yes","No") -> Yes | D17: =$B$7+A17*$B$8-1 -> 46292
A18: 6 | B18: =COUNTIF(Simulation!$O$2:$O$501,">="&$B$5)/$B$9 -> 1 | C18: =IF(B18>=$B$6,"Yes","No") -> Yes | D18: =$B$7+A18*$B$8-1 -> 46306
A19: 7 | B19: =COUNTIF(Simulation!$P$2:$P$501,">="&$B$5)/$B$9 -> 1 | C19: =IF(B19>=$B$6,"Yes","No") -> Yes | D19: =$B$7+A19*$B$8-1 -> 46320
A20: 8 | B20: =COUNTIF(Simulation!$Q$2:$Q$501,">="&$B$5)/$B$9 -> 1 | C20: =IF(B20>=$B$6,"Yes","No") -> Yes | D20: =$B$7+A20*$B$8-1 -> 46334
A22: Sprints needed at chosen confidence | B22: =IF(COUNTIF(C13:C20,"Yes")=0,">8",MATCH("Yes",C13:C20,0)) -> 3
A23: Forecast completion date | B23: =IF(COUNTIF(C13:C20,"Yes")=0,"Beyond 8 sprints",INDEX(D13:D20,MATCH("Yes",C13:C20,0))) -> 46264
A25: How to read: if the table says 85% for sprint 3, then in 85 of 100 simulated futures the remaining items were finished within 3 sprints, assuming the team's pace stays like its history.

Sheet Simulation
A1: Trial | B1: Draw S1 | C1: Draw S2 | D1: Draw S3 | E1: Draw S4 | F1: Draw S5 | G1: Draw S6 | H1: Draw S7 | I1: Draw S8 | J1: Cum 1 sprint(s) | K1: Cum 2 sprint(s) | L1: Cum 3 sprint(s) | M1: Cum 4 sprint(s) | N1: Cum 5 sprint(s) | O1: Cum 6 sprint(s) | P1: Cum 7 sprint(s) | Q1: Cum 8 sprint(s)
A2: 1 | B2: =INDEX(Sprint_Metrics!$F$7:$F$16,RANDBETWEEN(1,ROWS(Sprint_Metrics!$F$7:$F$16))) -> 8 | C2: =INDEX(Sprint_Metrics!$F$7:$F$16,RANDBETWEEN(1,ROWS(Sprint_Metrics!$F$7:$F$16))) -> 9 | D2: =INDEX(Sprint_Metrics!$F$7:$F$16,RANDBETWEEN(1,ROWS(Sprint_Metrics!$F$7:$F$16))) -> 11 | E2: =INDEX(Sprint_Metrics!$F$7:$F$16,RANDBETWEEN(1,ROWS(Sprint_Metrics!$F$7:$F$16))) -> 8 | F2: =INDEX(Sprint_Metrics!$F$7:$F$16,RANDBETWEEN(1,ROWS(Sprint_Metrics!$F$7:$F$16))) -> 11 | G2: =INDEX(Sprint_Metrics!$F$7:$F$16,RANDBETWEEN(1,ROWS(Sprint_Metrics!$F$7:$F$16))) -> 7 | H2: =INDEX(Sprint_Metrics!$F$7:$F$16,RANDBETWEEN(1,ROWS(Sprint_Metrics!$F$7:$F$16))) -> 7 | I2: =INDEX(Sprint_Metrics!$F$7:$F$16,RANDBETWEEN(1,ROWS(Sprint_Metrics!$F$7:$F$16))) -> 7 | J2: =B2 -> 8 | K2: =J2+C2 -> 17 | L2: =K2+D2 -> 28 | M2: =L2+E2 -> 36 | N2: =M2+F2 -> 47 | O2: =N2+G2 -> 54 | P2: =O2+H2 -> 61 | Q2: =P2+I2 -> 68
A3: 2 | B3: =INDEX(Sprint_Metrics!$F$7:$F$16,RANDBETWEEN(1,ROWS(Sprint_Metrics!$F$7:$F$16))) -> 11 | C3: =INDEX(Sprint_Metrics!$F$7:$F$16,RANDBETWEEN(1,ROWS(Sprint_Metrics!$F$7:$F$16))) -> 8 | D3: =INDEX(Sprint_Metrics!$F$7:$F$16,RANDBETWEEN(1,ROWS(Sprint_Metrics!$F$7:$F$16))) -> 9 | E3: =INDEX(Sprint_Metrics!$F$7:$F$16,RANDBETWEEN(1,ROWS(Sprint_Metrics!$F$7:$F$16))) -> 11 | F3: =INDEX(Sprint_Metrics!$F$7:$F$16,RANDBETWEEN(1,ROWS(Sprint_Metrics!$F$7:$F$16))) -> 8 | G3: =INDEX(Sprint_Metrics!$F$7:$F$16,RANDBETWEEN(1,ROWS(Sprint_Metrics!$F$7:$F$16))) -> 11 | H3: =INDEX(Sprint_Metrics!$F$7:$F$16,RANDBETWEEN(1,ROWS(Sprint_Metrics!$F$7:$F$16))) -> 7 | I3: =INDEX(Sprint_Metrics!$F$7:$F$16,RANDBETWEEN(1,ROWS(Sprint_Metrics!$F$7:$F$16))) -> 12 | J3: =B3 -> 11 | K3: =J3+C3 -> 19 | L3: =K3+D3 -> 28 | M3: =L3+E3 -> 39 | N3: =M3+F3 -> 47 | O3: =N3+G3 -> 58 | P3: =O3+H3 -> 65 | Q3: =P3+I3 -> 77
A4: 3 | B4: =INDEX(Sprint_Metrics!$F$7:$F$16,RANDBETWEEN(1,ROWS(Sprint_Metrics!$F$7:$F$16))) -> 11 | C4: =INDEX(Sprint_Metrics!$F$7:$F$16,RANDBETWEEN(1,ROWS(Sprint_Metrics!$F$7:$F$16))) -> 11 | D4: =INDEX(Sprint_Metrics!$F$7:$F$16,RANDBETWEEN(1,ROWS(Sprint_Metrics!$F$7:$F$16))) -> 7 | E4: =INDEX(Sprint_Metrics!$F$7:$F$16,RANDBETWEEN(1,ROWS(Sprint_Metrics!$F$7:$F$16))) -> 8 | F4: =INDEX(Sprint_Metrics!$F$7:$F$16,RANDBETWEEN(1,ROWS(Sprint_Metrics!$F$7:$F$16))) -> 12 | G4: =INDEX(Sprint_Metrics!$F$7:$F$16,RANDBETWEEN(1,ROWS(Sprint_Metrics!$F$7:$F$16))) -> 9 | H4: =INDEX(Sprint_Metrics!$F$7:$F$16,RANDBETWEEN(1,ROWS(Sprint_Metrics!$F$7:$F$16))) -> 8 | I4: =INDEX(Sprint_Metrics!$F$7:$F$16,RANDBETWEEN(1,ROWS(Sprint_Metrics!$F$7:$F$16))) -> 8 | J4: =B4 -> 11 | K4: =J4+C4 -> 22 | L4: =K4+D4 -> 29 | M4: =L4+E4 -> 37 | N4: =M4+F4 -> 49 | O4: =N4+G4 -> 58 | P4: =O4+H4 -> 66 | Q4: =P4+I4 -> 74
A5: 4 | B5: =INDEX(Sprint_Metrics!$F$7:$F$16,RANDBETWEEN(1,ROWS(Sprint_Metrics!$F$7:$F$16))) -> 9 | C5: =INDEX(Sprint_Metrics!$F$7:$F$16,RANDBETWEEN(1,ROWS(Sprint_Metrics!$F$7:$F$16))) -> 8 | D5: =INDEX(Sprint_Metrics!$F$7:$F$16,RANDBETWEEN(1,ROWS(Sprint_Metrics!$F$7:$F$16))) -> 9 | E5: =INDEX(Sprint_Metrics!$F$7:$F$16,RANDBETWEEN(1,ROWS(Sprint_Metrics!$F$7:$F$16))) -> 8 | F5: =INDEX(Sprint_Metrics!$F$7:$F$16,RANDBETWEEN(1,ROWS(Sprint_Metrics!$F$7:$F$16))) -> 8 | G5: =INDEX(Sprint_Metrics!$F$7:$F$16,RANDBETWEEN(1,ROWS(Sprint_Metrics!$F$7:$F$16))) -> 8 | H5: =INDEX(Sprint_Metrics!$F$7:$F$16,RANDBETWEEN(1,ROWS(Sprint_Metrics!$F$7:$F$16))) -> 11 | I5: =INDEX(Sprint_Metrics!$F$7:$F$16,RANDBETWEEN(1,ROWS(Sprint_Metrics!$F$7:$F$16))) -> 9 | J5: =B5 -> 9 | K5: =J5+C5 -> 17 | L5: =K5+D5 -> 26 | M5: =L5+E5 -> 34 | N5: =M5+F5 -> 42 | O5: =N5+G5 -> 50 | P5: =O5+H5 -> 61 | Q5: =P5+I5 -> 70
A6: 5 | B6: =INDEX(Sprint_Metrics!$F$7:$F$16,RANDBETWEEN(1,ROWS(Sprint_Metrics!$F$7:$F$16))) -> 8 | C6: =INDEX(Sprint_Metrics!$F$7:$F$16,RANDBETWEEN(1,ROWS(Sprint_Metrics!$F$7:$F$16))) -> 12 | D6: =INDEX(Sprint_Metrics!$F$7:$F$16,RANDBETWEEN(1,ROWS(Sprint_Metrics!$F$7:$F$16))) -> 9 | E6: =INDEX(Sprint_Metrics!$F$7:$F$16,RANDBETWEEN(1,ROWS(Sprint_Metrics!$F$7:$F$16))) -> 12 | F6: =INDEX(Sprint_Metrics!$F$7:$F$16,RANDBETWEEN(1,ROWS(Sprint_Metrics!$F$7:$F$16))) -> 7 | G6: =INDEX(Sprint_Metrics!$F$7:$F$16,RANDBETWEEN(1,ROWS(Sprint_Metrics!$F$7:$F$16))) -> 12 | H6: =INDEX(Sprint_Metrics!$F$7:$F$16,RANDBETWEEN(1,ROWS(Sprint_Metrics!$F$7:$F$16))) -> 7 | I6: =INDEX(Sprint_Metrics!$F$7:$F$16,RANDBETWEEN(1,ROWS(Sprint_Metrics!$F$7:$F$16))) -> 11 | J6: =B6 -> 8 | K6: =J6+C6 -> 20 | L6: =K6+D6 -> 29 | M6: =L6+E6 -> 41 | N6: =M6+F6 -> 48 | O6: =N6+G6 -> 60 | P6: =O6+H6 -> 67 | Q6: =P6+I6 -> 78
A7: 6 | B7: =INDEX(Sprint_Metrics!$F$7:$F$16,RANDBETWEEN(1,ROWS(Sprint_Metrics!$F$7:$F$16))) -> 12 | C7: =INDEX(Sprint_Metrics!$F$7:$F$16,RANDBETWEEN(1,ROWS(Sprint_Metrics!$F$7:$F$16))) -> 7 | D7: =INDEX(Sprint_Metrics!$F$7:$F$16,RANDBETWEEN(1,ROWS(Sprint_Metrics!$F$7:$F$16))) -> 11 | E7: =INDEX(Sprint_Metrics!$F$7:$F$16,RANDBETWEEN(1,ROWS(Sprint_Metrics!$F$7:$F$16))) -> 7 | F7: =INDEX(Sprint_Metrics!$F$7:$F$16,RANDBETWEEN(1,ROWS(Sprint_Metrics!$F$7:$F$16))) -> 8 | G7: =INDEX(Sprint_Metrics!$F$7:$F$16,RANDBETWEEN(1,ROWS(Sprint_Metrics!$F$7:$F$16))) -> 11 | H7: =INDEX(Sprint_Metrics!$F$7:$F$16,RANDBETWEEN(1,ROWS(Sprint_Metrics!$F$7:$F$16))) -> 9 | I7: =INDEX(Sprint_Metrics!$F$7:$F$16,RANDBETWEEN(1,ROWS(Sprint_Metrics!$F$7:$F$16))) -> 12 | J7: =B7 -> 12 | K7: =J7+C7 -> 19 | L7: =K7+D7 -> 30 | M7: =L7+E7 -> 37 | N7: =M7+F7 -> 45 | O7: =N7+G7 -> 56 | P7: =O7+H7 -> 65 | Q7: =P7+I7 -> 77
A8: 7 | B8: =INDEX(Sprint_Metrics!$F$7:$F$16,RANDBETWEEN(1,ROWS(Sprint_Metrics!$F$7:$F$16))) -> 12 | C8: =INDEX(Sprint_Metrics!$F$7:$F$16,RANDBETWEEN(1,ROWS(Sprint_Metrics!$F$7:$F$16))) -> 11 | D8: =INDEX(Sprint_Metrics!$F$7:$F$16,RANDBETWEEN(1,ROWS(Sprint_Metrics!$F$7:$F$16))) -> 9 | E8: =INDEX(Sprint_Metrics!$F$7:$F$16,RANDBETWEEN(1,ROWS(Sprint_Metrics!$F$7:$F$16))) -> 8 | F8: =INDEX(Sprint_Metrics!$F$7:$F$16,RANDBETWEEN(1,ROWS(Sprint_Metrics!$F$7:$F$16))) -> 11 | G8: =INDEX(Sprint_Metrics!$F$7:$F$16,RANDBETWEEN(1,ROWS(Sprint_Metrics!$F$7:$F$16))) -> 8 | H8: =INDEX(Sprint_Metrics!$F$7:$F$16,RANDBETWEEN(1,ROWS(Sprint_Metrics!$F$7:$F$16))) -> 9 | I8: =INDEX(Sprint_Metrics!$F$7:$F$16,RANDBETWEEN(1,ROWS(Sprint_Metrics!$F$7:$F$16))) -> 9 | J8: =B8 -> 12 | K8: =J8+C8 -> 23 | L8: =K8+D8 -> 32 | M8: =L8+E8 -> 40 | N8: =M8+F8 -> 51 | O8: =N8+G8 -> 59 | P8: =O8+H8 -> 68 | Q8: =P8+I8 -> 77
A9: 8 | B9: =INDEX(Sprint_Metrics!$F$7:$F$16,RANDBETWEEN(1,ROWS(Sprint_Metrics!$F$7:$F$16))) -> 11 | C9: =INDEX(Sprint_Metrics!$F$7:$F$16,RANDBETWEEN(1,ROWS(Sprint_Metrics!$F$7:$F$16))) -> 12 | D9: =INDEX(Sprint_Metrics!$F$7:$F$16,RANDBETWEEN(1,ROWS(Sprint_Metrics!$F$7:$F$16))) -> 12 | E9: =INDEX(Sprint_Metrics!$F$7:$F$16,RANDBETWEEN(1,ROWS(Sprint_Metrics!$F$7:$F$16))) -> 7 | F9: =INDEX(Sprint_Metrics!$F$7:$F$16,RANDBETWEEN(1,ROWS(Sprint_Metrics!$F$7:$F$16))) -> 7 | G9: =INDEX(Sprint_Metrics!$F$7:$F$16,RANDBETWEEN(1,ROWS(Sprint_Metrics!$F$7:$F$16))) -> 7 | H9: =INDEX(Sprint_Metrics!$F$7:$F$16,RANDBETWEEN(1,ROWS(Sprint_Metrics!$F$7:$F$16))) -> 11 | I9: =INDEX(Sprint_Metrics!$F$7:$F$16,RANDBETWEEN(1,ROWS(Sprint_Metrics!$F$7:$F$16))) -> 8 | J9: =B9 -> 11 | K9: =J9+C9 -> 23 | L9: =K9+D9 -> 35 | M9: =L9+E9 -> 42 | N9: =M9+F9 -> 49 | O9: =N9+G9 -> 56 | P9: =O9+H9 -> 67 | Q9: =P9+I9 -> 75
A10: 9 | B10: =INDEX(Sprint_Metrics!$F$7:$F$16,RANDBETWEEN(1,ROWS(Sprint_Metrics!$F$7:$F$16))) -> 11 | C10: =INDEX(Sprint_Metrics!$F$7:$F$16,RANDBETWEEN(1,ROWS(Sprint_Metrics!$F$7:$F$16))) -> 9 | D10: =INDEX(Sprint_Metrics!$F$7:$F$16,RANDBETWEEN(1,ROWS(Sprint_Metrics!$F$7:$F$16))) -> 12 | E10: =INDEX(Sprint_Metrics!$F$7:$F$16,RANDBETWEEN(1,ROWS(Sprint_Metrics!$F$7:$F$16))) -> 7 | F10: =INDEX(Sprint_Metrics!$F$7:$F$16,RANDBETWEEN(1,ROWS(Sprint_Metrics!$F$7:$F$16))) -> 12 | G10: =INDEX(Sprint_Metrics!$F$7:$F$16,RANDBETWEEN(1,ROWS(Sprint_Metrics!$F$7:$F$16))) -> 11 | H10: =INDEX(Sprint_Metrics!$F$7:$F$16,RANDBETWEEN(1,ROWS(Sprint_Metrics!$F$7:$F$16))) -> 9 | I10: =INDEX(Sprint_Metrics!$F$7:$F$16,RANDBETWEEN(1,ROWS(Sprint_Metrics!$F$7:$F$16))) -> 7 | J10: =B10 -> 11 | K10: =J10+C10 -> 20 | L10: =K10+D10 -> 32 | M10: =L10+E10 -> 39 | N10: =M10+F10 -> 51 | O10: =N10+G10 -> 62 | P10: =O10+H10 -> 71 | Q10: =P10+I10 -> 78
A11: 10 | B11: =INDEX(Sprint_Metrics!$F$7:$F$16,RANDBETWEEN(1,ROWS(Sprint_Metrics!$F$7:$F$16))) -> 7 | C11: =INDEX(Sprint_Metrics!$F$7:$F$16,RANDBETWEEN(1,ROWS(Sprint_Metrics!$F$7:$F$16))) -> 8 | D11: =INDEX(Sprint_Metrics!$F$7:$F$16,RANDBETWEEN(1,ROWS(Sprint_Metrics!$F$7:$F$16))) -> 9 | E11: =INDEX(Sprint_Metrics!$F$7:$F$16,RANDBETWEEN(1,ROWS(Sprint_Metrics!$F$7:$F$16))) -> 8 | F11: =INDEX(Sprint_Metrics!$F$7:$F$16,RANDBETWEEN(1,ROWS(Sprint_Metrics!$F$7:$F$16))) -> 11 | G11: =INDEX(Sprint_Metrics!$F$7:$F$16,RANDBETWEEN(1,ROWS(Sprint_Metrics!$F$7:$F$16))) -> 7 | H11: =INDEX(Sprint_Metrics!$F$7:$F$16,RANDBETWEEN(1,ROWS(Sprint_Metrics!$F$7:$F$16))) -> 11 | I11: =INDEX(Sprint_Metrics!$F$7:$F$16,RANDBETWEEN(1,ROWS(Sprint_Metrics!$F$7:$F$16))) -> 7 | J11: =B11 -> 7 | K11: =J11+C11 -> 15 | L11: =K11+D11 -> 24 | M11: =L11+E11 -> 32 | N11: =M11+F11 -> 43 | O11: =N11+G11 -> 50 | P11: =O11+H11 -> 61 | Q11: =P11+I11 -> 68
A12: 11 | B12: =INDEX(Sprint_Metrics!$F$7:$F$16,RANDBETWEEN(1,ROWS(Sprint_Metrics!$F$7:$F$16))) -> 11 | C12: =INDEX(Sprint_Metrics!$F$7:$F$16,RANDBETWEEN(1,ROWS(Sprint_Metrics!$F$7:$F$16))) -> 8 | D12: =INDEX(Sprint_Metrics!$F$7:$F$16,RANDBETWEEN(1,ROWS(Sprint_Metrics!$F$7:$F$16))) -> 9 | E12: =INDEX(Sprint_Metrics!$F$7:$F$16,RANDBETWEEN(1,ROWS(Sprint_Metrics!$F$7:$F$16))) -> 9 | F12: =INDEX(Sprint_Metrics!$F$7:$F$16,RANDBETWEEN(1,ROWS(Sprint_Metrics!$F$7:$F$16))) -> 8 | G12: =INDEX(Sprint_Metrics!$F$7:$F$16,RANDBETWEEN(1,ROWS(Sprint_Metrics!$F$7:$F$16))) -> 11 | H12: =INDEX(Sprint_Metrics!$F$7:$F$16,RANDBETWEEN(1,ROWS(Sprint_Metrics!$F$7:$F$16))) -> 11 | I12: =INDEX(Sprint_Metrics!$F$7:$F$16,RANDBETWEEN(1,ROWS(Sprint_Metrics!$F$7:$F$16))) -> 7 | J12: =B12 -> 11 | K12: =J12+C12 -> 19 | L12: =K12+D12 -> 28 | M12: =L12+E12 -> 37 | N12: =M12+F12 -> 45 | O12: =N12+G12 -> 56 | P12: =O12+H12 -> 67 | Q12: =P12+I12 -> 74
A13: 12 | B13: =INDEX(Sprint_Metrics!$F$7:$F$16,RANDBETWEEN(1,ROWS(Sprint_Metrics!$F$7:$F$16))) -> 11 | C13: =INDEX(Sprint_Metrics!$F$7:$F$16,RANDBETWEEN(1,ROWS(Sprint_Metrics!$F$7:$F$16))) -> 7 | D13: =INDEX(Sprint_Metrics!$F$7:$F$16,RANDBETWEEN(1,ROWS(Sprint_Metrics!$F$7:$F$16))) -> 12 | E13: =INDEX(Sprint_Metrics!$F$7:$F$16,RANDBETWEEN(1,ROWS(Sprint_Metrics!$F$7:$F$16))) -> 7 | F13: =INDEX(Sprint_Metrics!$F$7:$F$16,RANDBETWEEN(1,ROWS(Sprint_Metrics!$F$7:$F$16))) -> 7 | G13: =INDEX(Sprint_Metrics!$F$7:$F$16,RANDBETWEEN(1,ROWS(Sprint_Metrics!$F$7:$F$16))) -> 9 | H13: =INDEX(Sprint_Metrics!$F$7:$F$16,RANDBETWEEN(1,ROWS(Sprint_Metrics!$F$7:$F$16))) -> 8 | I13: =INDEX(Sprint_Metrics!$F$7:$F$16,RANDBETWEEN(1,ROWS(Sprint_Metrics!$F$7:$F$16))) -> 8 | J13: =B13 -> 11 | K13: =J13+C13 -> 18 | L13: =K13+D13 -> 30 | M13: =L13+E13 -> 37 | N13: =M13+F13 -> 44 | O13: =N13+G13 -> 53 | P13: =O13+H13 -> 61 | Q13: =P13+I13 -> 69
... A501: 500 | B501: =INDEX(Sprint_Metrics!$F$7:$F$16,RANDBETWEEN(1,ROWS(Sprint_Metrics!$F$7:$F$16))) -> 8 | C501: =INDEX(Sprint_Metrics!$F$7:$F$16,RANDBETWEEN(1,ROWS(Sprint_Metrics!$F$7:$F$16))) -> 9 | D501: =INDEX(Sprint_Metrics!$F$7:$F$16,RANDBETWEEN(1,ROWS(Sprint_Metrics!$F$7:$F$16))) -> 7 | E501: =INDEX(Sprint_Metrics!$F$7:$F$16,RANDBETWEEN(1,ROWS(Sprint_Metrics!$F$7:$F$16))) -> 8 | F501: =INDEX(Sprint_Metrics!$F$7:$F$16,RANDBETWEEN(1,ROWS(Sprint_Metrics!$F$7:$F$16))) -> 7 | G501: =INDEX(Sprint_Metrics!$F$7:$F$16,RANDBETWEEN(1,ROWS(Sprint_Metrics!$F$7:$F$16))) -> 11 | H501: =INDEX(Sprint_Metrics!$F$7:$F$16,RANDBETWEEN(1,ROWS(Sprint_Metrics!$F$7:$F$16))) -> 8 | I501: =INDEX(Sprint_Metrics!$F$7:$F$16,RANDBETWEEN(1,ROWS(Sprint_Metrics!$F$7:$F$16))) -> 7 | J501: =B501 -> 8 | K501: =J501+C501 -> 17 | L501: =K501+D501 -> 24 | M501: =L501+E501 -> 32 | N501: =M501+F501 -> 39 | O501: =N501+G501 -> 50 | P501: =O501+H501 -> 58 | Q501: =P501+I501 -> 65

Sheet Jira_Data
A1: Issue key | B1: Summary | C1: Issue Type | D1: Status | E1: Story Points | F1: Sprint Committed | G1: Created | H1: Started | I1: Resolved | J1: Cycle Time (days) | K1: Lead Time (days)
A2: DEMO-101 | B2: Add role permissions to mobile app | C2: Story | D2: Done | E2: 2 | F2: Sprint 1 | G2: 46060 | H2: 46085 | I2: 46091 | J2: =IF(AND(ISNUMBER(H2),ISNUMBER(I2)),I2-H2,"") -> 6 | K2: =IF(AND(ISNUMBER(G2),ISNUMBER(I2)),I2-G2,"") -> 31
A3: DEMO-102 | B3: Update API documentation | C3: Task | D3: Done | E3: 2 | F3: Sprint 1 | G3: 46061 | H3: 46090 | I3: 46098 | J3: =IF(AND(ISNUMBER(H3),ISNUMBER(I3)),I3-H3,"") -> 8 | K3: =IF(AND(ISNUMBER(G3),ISNUMBER(I3)),I3-G3,"") -> 37
A4: DEMO-103 | B4: Update CI pipeline config | C4: Task | D4: Done | E4: 2 | F4: Sprint 1 | G4: 46063 | H4: 46087 | I4: 46091 | J4: =IF(AND(ISNUMBER(H4),ISNUMBER(I4)),I4-H4,"") -> 4 | K4: =IF(AND(ISNUMBER(G4),ISNUMBER(I4)),I4-G4,"") -> 28
A5: DEMO-104 | B5: Update database indices | C5: Task | D5: Done | E5: 5 | F5: Sprint 1 | G5: 46065 | H5: 46083 | I5: 46090 | J5: =IF(AND(ISNUMBER(H5),ISNUMBER(I5)),I5-H5,"") -> 7 | K5: =IF(AND(ISNUMBER(G5),ISNUMBER(I5)),I5-G5,"") -> 25
A6: DEMO-105 | B6: Add search suggestions to mobile app | C6: Story | D6: Done | E6: 1 | F6: Sprint 2 | G6: 46074 | H6: 46098 | I6: 46101 | J6: =IF(AND(ISNUMBER(H6),ISNUMBER(I6)),I6-H6,"") -> 3 | K6: =IF(AND(ISNUMBER(G6),ISNUMBER(I6)),I6-G6,"") -> 27
A7: DEMO-106 | B7: Add audit log to reporting module | C7: Story | D7: Done | E7: 1 | F7: Sprint 1 | G7: 46075 | H7: 46084 | I7: 46085 | J7: =IF(AND(ISNUMBER(H7),ISNUMBER(I7)),I7-H7,"") -> 1 | K7: =IF(AND(ISNUMBER(G7),ISNUMBER(I7)),I7-G7,"") -> 10
A8: DEMO-107 | B8: Add audit log to mobile app | C8: Story | D8: Done | E8: 3 | F8: Sprint 2 | G8: 46075 | H8: 46100 | I8: 46108 | J8: =IF(AND(ISNUMBER(H8),ISNUMBER(I8)),I8-H8,"") -> 8 | K8: =IF(AND(ISNUMBER(G8),ISNUMBER(I8)),I8-G8,"") -> 33
A9: DEMO-108 | B9: Fix missing validation in customer portal | C9: Bug | D9: Done | E9: 1 | F9: Sprint 1 | G9: 46076 | H9: 46091 | I9: 46097 | J9: =IF(AND(ISNUMBER(H9),ISNUMBER(I9)),I9-H9,"") -> 6 | K9: =IF(AND(ISNUMBER(G9),ISNUMBER(I9)),I9-G9,"") -> 21
A10: DEMO-109 | B10: Fix broken pagination in reporting module | C10: Bug | D10: Done | E10: 1 | F10: Sprint 1 | G10: 46079 | H10: 46085 | I10: 46090 | J10: =IF(AND(ISNUMBER(H10),ISNUMBER(I10)),I10-H10,"") -> 5 | K10: =IF(AND(ISNUMBER(G10),ISNUMBER(I10)),I10-G10,"") -> 11
A11: DEMO-110 | B11: Fix missing validation in customer portal | C11: Bug | D11: Done | E11: 1 | F11: Sprint 2 | G11: 46079 | H11: 46104 | I11: 46107 | J11: =IF(AND(ISNUMBER(H11),ISNUMBER(I11)),I11-H11,"") -> 3 | K11: =IF(AND(ISNUMBER(G11),ISNUMBER(I11)),I11-G11,"") -> 28
A12: DEMO-111 | B12: Fix timeout on load in checkout | C12: Bug | D12: Done | E12: 2 | F12: Sprint 1 | G12: 46080 | H12: 46090 | I12: 46093 | J12: =IF(AND(ISNUMBER(H12),ISNUMBER(I12)),I12-H12,"") -> 3 | K12: =IF(AND(ISNUMBER(G12),ISNUMBER(I12)),I12-G12,"") -> 13
A13: DEMO-112 | B13: Add password reset flow to admin console | C13: Story | D13: Done | E13: 1 | F13: Sprint 2 | G13: 46080 | H13: 46099 | I13: 46101 | J13: =IF(AND(ISNUMBER(H13),ISNUMBER(I13)),I13-H13,"") -> 2 | K13: =IF(AND(ISNUMBER(G13),ISNUMBER(I13)),I13-G13,"") -> 21
... A76: DEMO-175 | B76: Add role permissions to reporting module | C76: Story | D76: Done | E76: 3 | F76: Sprint 8 | G76: 46176 | H76: 46188 | I76: 46191 | J76: =IF(AND(ISNUMBER(H76),ISNUMBER(I76)),I76-H76,"") -> 3 | K76: =IF(AND(ISNUMBER(G76),ISNUMBER(I76)),I76-G76,"") -> 15
A77: DEMO-176 | B77: Add audit log to customer portal | C77: Story | D77: To Do | E77: 5 | F77: Backlog | G77: 46176 | J77: =IF(AND(ISNUMBER(H77),ISNUMBER(I77)),I77-H77,"") | K77: =IF(AND(ISNUMBER(G77),ISNUMBER(I77)),I77-G77,"")
A78: DEMO-177 | B78: Add email notifications to reporting module | C78: Story | D78: To Do | E78: 8 | F78: Backlog | G78: 46176 | J78: =IF(AND(ISNUMBER(H78),ISNUMBER(I78)),I78-H78,"") | K78: =IF(AND(ISNUMBER(G78),ISNUMBER(I78)),I78-G78,"")
A79: DEMO-178 | B79: Add SSO login to mobile app | C79: Story | D79: Done | E79: 8 | F79: Sprint 9 | G79: 46177 | H79: 46198 | I79: 46217 | J79: =IF(AND(ISNUMBER(H79),ISNUMBER(I79)),I79-H79,"") -> 19 | K79: =IF(AND(ISNUMBER(G79),ISNUMBER(I79)),I79-G79,"") -> 40
A80: DEMO-179 | B80: Add export to CSV to customer portal | C80: Story | D80: Done | E80: 5 | F80: Sprint 9 | G80: 46178 | H80: 46199 | I80: 46205 | J80: =IF(AND(ISNUMBER(H80),ISNUMBER(I80)),I80-H80,"") -> 6 | K80: =IF(AND(ISNUMBER(G80),ISNUMBER(I80)),I80-G80,"") -> 27
A81: DEMO-180 | B81: Fix missing validation in mobile app | C81: Bug | D81: To Do | E81: 1 | F81: Backlog | G81: 46179 | J81: =IF(AND(ISNUMBER(H81),ISNUMBER(I81)),I81-H81,"") | K81: =IF(AND(ISNUMBER(G81),ISNUMBER(I81)),I81-G81,"")
A82: DEMO-181 | B82: Add dark mode to customer portal | C82: Story | D82: Done | E82: 1 | F82: Sprint 8 | G82: 46180 | H82: 46184 | I82: 46188 | J82: =IF(AND(ISNUMBER(H82),ISNUMBER(I82)),I82-H82,"") -> 4 | K82: =IF(AND(ISNUMBER(G82),ISNUMBER(I82)),I82-G82,"") -> 8
A83: DEMO-182 | B83: Add role permissions to reporting module | C83: Story | D83: Done | E83: 8 | F83: Sprint 9 | G83: 46180 | H83: 46203 | I83: 46209 | J83: =IF(AND(ISNUMBER(H83),ISNUMBER(I83)),I83-H83,"") -> 6 | K83: =IF(AND(ISNUMBER(G83),ISNUMBER(I83)),I83-G83,"") -> 29
A84: DEMO-183 | B84: Add audit log to mobile app | C84: Story | D84: Done | E84: 1 | F84: Sprint 9 | G84: 46183 | H84: 46202 | I84: 46205 | J84: =IF(AND(ISNUMBER(H84),ISNUMBER(I84)),I84-H84,"") -> 3 | K84: =IF(AND(ISNUMBER(G84),ISNUMBER(I84)),I84-G84,"") -> 22
A85: DEMO-184 | B85: Add dark mode to customer portal | C85: Story | D85: To Do | E85: 5 | F85: Backlog | G85: 46183 | J85: =IF(AND(ISNUMBER(H85),ISNUMBER(I85)),I85-H85,"") | K85: =IF(AND(ISNUMBER(G85),ISNUMBER(I85)),I85-G85,"")
A86: DEMO-185 | B86: Add export to CSV to admin console | C86: Story | D86: Done | E86: 2 | F86: Sprint 10 | G86: 46185 | H86: 46217 | I86: 46223 | J86: =IF(AND(ISNUMBER(H86),ISNUMBER(I86)),I86-H86,"") -> 6 | K86: =IF(AND(ISNUMBER(G86),ISNUMBER(I86)),I86-G86,"") -> 38
A87: DEMO-186 | B87: Add profile avatars to customer portal | C87: Story | D87: Done | E87: 2 | F87: Sprint 10 | G87: 46185 | H87: 46209 | I87: 46213 | J87: =IF(AND(ISNUMBER(H87),ISNUMBER(I87)),I87-H87,"") -> 4 | K87: =IF(AND(ISNUMBER(G87),ISNUMBER(I87)),I87-G87,"") -> 28
A88: DEMO-187 | B88: Add dark mode to mobile app | C88: Story | D88: Done | E88: 5 | F88: Sprint 9 | G88: 46191 | H88: 46199 | I88: 46202 | J88: =IF(AND(ISNUMBER(H88),ISNUMBER(I88)),I88-H88,"") -> 3 | K88: =IF(AND(ISNUMBER(G88),ISNUMBER(I88)),I88-G88,"") -> 11
A89: DEMO-188 | B89: Update API documentation | C89: Task | D89: To Do | E89: 5 | F89: Backlog | G89: 46191 | J89: =IF(AND(ISNUMBER(H89),ISNUMBER(I89)),I89-H89,"") | K89: =IF(AND(ISNUMBER(G89),ISNUMBER(I89)),I89-G89,"")
A90: DEMO-189 | B90: Fix incorrect totals in customer portal | C90: Bug | D90: Done | E90: 1 | F90: Sprint 9 | G90: 46192 | H90: 46202 | I90: 46203 | J90: =IF(AND(ISNUMBER(H90),ISNUMBER(I90)),I90-H90,"") -> 1 | K90: =IF(AND(ISNUMBER(G90),ISNUMBER(I90)),I90-G90,"") -> 11
A91: DEMO-190 | B91: Add export to CSV to mobile app | C91: Story | D91: Done | E91: 3 | F91: Sprint 9 | G91: 46192 | H91: 46203 | I91: 46212 | J91: =IF(AND(ISNUMBER(H91),ISNUMBER(I91)),I91-H91,"") -> 9 | K91: =IF(AND(ISNUMBER(G91),ISNUMBER(I91)),I91-G91,"") -> 20
A92: DEMO-191 | B92: Add usage report to reporting module | C92: Story | D92: Done | E92: 2 | F92: Sprint 9 | G92: 46193 | H92: 46197 | I92: 46198 | J92: =IF(AND(ISNUMBER(H92),ISNUMBER(I92)),I92-H92,"") -> 1 | K92: =IF(AND(ISNUMBER(G92),ISNUMBER(I92)),I92-G92,"") -> 5
A93: DEMO-192 | B93: Add export to CSV to mobile app | C93: Story | D93: To Do | E93: 3 | F93: Backlog | G93: 46193 | J93: =IF(AND(ISNUMBER(H93),ISNUMBER(I93)),I93-H93,"") | K93: =IF(AND(ISNUMBER(G93),ISNUMBER(I93)),I93-G93,"")
A94: DEMO-193 | B94: Fix missing validation in customer portal | C94: Bug | D94: To Do | E94: 1 | F94: Backlog | G94: 46193 | J94: =IF(AND(ISNUMBER(H94),ISNUMBER(I94)),I94-H94,"") | K94: =IF(AND(ISNUMBER(G94),ISNUMBER(I94)),I94-G94,"")
A95: DEMO-194 | B95: Add export to CSV to checkout | C95: Story | D95: To Do | E95: 1 | F95: Backlog | G95: 46193 | J95: =IF(AND(ISNUMBER(H95),ISNUMBER(I95)),I95-H95,"") | K95: =IF(AND(ISNUMBER(G95),ISNUMBER(I95)),I95-G95,"")
A96: DEMO-195 | B96: Update CI pipeline config | C96: Task | D96: Done | E96: 1 | F96: Sprint 9 | G96: 46194 | H96: 46195 | I96: 46197 | J96: =IF(AND(ISNUMBER(H96),ISNUMBER(I96)),I96-H96,"") -> 2 | K96: =IF(AND(ISNUMBER(G96),ISNUMBER(I96)),I96-G96,"") -> 3
A97: DEMO-196 | B97: Update API documentation | C97: Task | D97: Done | E97: 2 | F97: Sprint 10 | G97: 46195 | H97: 46211 | I97: 46225 | J97: =IF(AND(ISNUMBER(H97),ISNUMBER(I97)),I97-H97,"") -> 14 | K97: =IF(AND(ISNUMBER(G97),ISNUMBER(I97)),I97-G97,"") -> 30
A98: DEMO-197 | B98: Add API rate limiting to customer portal | C98: Story | D98: Done | E98: 3 | F98: Sprint 10 | G98: 46195 | H98: 46213 | I98: 46218 | J98: =IF(AND(ISNUMBER(H98),ISNUMBER(I98)),I98-H98,"") -> 5 | K98: =IF(AND(ISNUMBER(G98),ISNUMBER(I98)),I98-G98,"") -> 23
A99: DEMO-198 | B99: Add export to CSV to mobile app | C99: Story | D99: To Do | E99: 5 | F99: Backlog | G99: 46196 | J99: =IF(AND(ISNUMBER(H99),ISNUMBER(I99)),I99-H99,"") | K99: =IF(AND(ISNUMBER(G99),ISNUMBER(I99)),I99-G99,"")
A100: DEMO-199 | B100: Update API documentation | C100: Task | D100: Done | E100: 3 | F100: Sprint 10 | G100: 46197 | H100: 46216 | I100: 46223 | J100: =IF(AND(ISNUMBER(H100),ISNUMBER(I100)),I100-H100,"") -> 7 | K100: =IF(AND(ISNUMBER(G100),ISNUMBER(I100)),I100-G100,"") -> 26
A101: DEMO-200 | B101: Fix missing validation in admin console | C101: Bug | D101: Done | E101: 3 | F101: Sprint 10 | G101: 46198 | H101: 46212 | I101: 46225 | J101: =IF(AND(ISNUMBER(H101),ISNUMBER(I101)),I101-H101,"") -> 13 | K101: =IF(AND(ISNUMBER(G101),ISNUMBER(I101)),I101-G101,"") -> 27
A102: DEMO-201 | B102: Update CI pipeline config | C102: Task | D102: Done | E102: 1 | F102: Sprint 10 | G102: 46200 | H102: 46216 | I102: 46218 | J102: =IF(AND(ISNUMBER(H102),ISNUMBER(I102)),I102-H102,"") -> 2 | K102: =IF(AND(ISNUMBER(G102),ISNUMBER(I102)),I102-G102,"") -> 18
...
